D:\OTUS\venv\Scripts\python.exe D:/OTUS/BasePython/lessons/lesson.16/orm4_session_and_relations.py
2021-12-12 22:17:30,078 INFO sqlalchemy.engine.Engine BEGIN (implicit)
2021-12-12 22:17:30,078 INFO sqlalchemy.engine.Engine PRAGMA main.table_info("users")
2021-12-12 22:17:30,078 INFO sqlalchemy.engine.Engine [raw sql] ()
2021-12-12 22:17:30,078 INFO sqlalchemy.engine.Engine PRAGMA main.table_info("posts")
2021-12-12 22:17:30,078 INFO sqlalchemy.engine.Engine [raw sql] ()
2021-12-12 22:17:30,090 INFO sqlalchemy.engine.Engine COMMIT
2021-12-12 22:17:30,091 INFO sqlalchemy.engine.Engine BEGIN (implicit)
2021-12-12 22:17:30,091 INFO sqlalchemy.engine.Engine SELECT users.id AS users_id, users.username AS users_username, users.is_staff AS users_is_staff, users.created_at AS users_created_at 
FROM users 
WHERE users.username = ?
2021-12-12 22:17:30,091 INFO sqlalchemy.engine.Engine [generated in 0.00029s] ('john',)
2021-12-12 22:17:30,091 INFO sqlalchemy.engine.Engine SELECT users.id AS users_id, users.username AS users_username, users.is_staff AS users_is_staff, users.created_at AS users_created_at 
FROM users 
WHERE users.username = ?
2021-12-12 22:17:30,091 INFO sqlalchemy.engine.Engine [cached since 0.002101s ago] ('sam',)
None
None
prepare post Post(id=None, title='Flask lesson', author_id=None, created_at=None)
2021-12-12 22:17:30,091 INFO sqlalchemy.engine.Engine INSERT INTO posts (title, created_at, author_id) VALUES (?, ?, ?)
2021-12-12 22:17:30,091 INFO sqlalchemy.engine.Engine [generated in 0.00030s] ('Flask lesson', '2021-12-12 19:17:30.091338', None)
2021-12-12 22:17:30,091 INFO sqlalchemy.engine.Engine ROLLBACK
Traceback (most recent call last):
  File "D:\OTUS\venv\lib\site-packages\sqlalchemy\engine\base.py", line 1799, in _execute_context
    self.dialect.do_execute(
  File "D:\OTUS\venv\lib\site-packages\sqlalchemy\engine\default.py", line 717, in do_execute
    cursor.execute(statement, parameters)
sqlite3.IntegrityError: NOT NULL constraint failed: posts.author_id

The above exception was the direct cause of the following exception:

Traceback (most recent call last):
  File "D:\OTUS\BasePython\lessons\lesson.16\orm4_session_and_relations.py", line 264, in <module>
    main()
  File "D:\OTUS\BasePython\lessons\lesson.16\orm4_session_and_relations.py", line 253, in main
    create_post(user_john, "Flask lesson")
  File "D:\OTUS\BasePython\lessons\lesson.16\orm4_session_and_relations.py", line 144, in create_post
    session.commit()
  File "D:\OTUS\venv\lib\site-packages\sqlalchemy\orm\session.py", line 1428, in commit
    self._transaction.commit(_to_root=self.future)
  File "D:\OTUS\venv\lib\site-packages\sqlalchemy\orm\session.py", line 829, in commit
    self._prepare_impl()
  File "D:\OTUS\venv\lib\site-packages\sqlalchemy\orm\session.py", line 808, in _prepare_impl
    self.session.flush()
  File "D:\OTUS\venv\lib\site-packages\sqlalchemy\orm\session.py", line 3339, in flush
    self._flush(objects)
  File "D:\OTUS\venv\lib\site-packages\sqlalchemy\orm\session.py", line 3479, in _flush
    transaction.rollback(_capture_exception=True)
  File "D:\OTUS\venv\lib\site-packages\sqlalchemy\util\langhelpers.py", line 70, in __exit__
    compat.raise_(
  File "D:\OTUS\venv\lib\site-packages\sqlalchemy\util\compat.py", line 207, in raise_
    raise exception
  File "D:\OTUS\venv\lib\site-packages\sqlalchemy\orm\session.py", line 3439, in _flush
    flush_context.execute()
  File "D:\OTUS\venv\lib\site-packages\sqlalchemy\orm\unitofwork.py", line 456, in execute
    rec.execute(self)
  File "D:\OTUS\venv\lib\site-packages\sqlalchemy\orm\unitofwork.py", line 630, in execute
    util.preloaded.orm_persistence.save_obj(
  File "D:\OTUS\venv\lib\site-packages\sqlalchemy\orm\persistence.py", line 242, in save_obj
    _emit_insert_statements(
  File "D:\OTUS\venv\lib\site-packages\sqlalchemy\orm\persistence.py", line 1219, in _emit_insert_statements
    result = connection._execute_20(
  File "D:\OTUS\venv\lib\site-packages\sqlalchemy\engine\base.py", line 1611, in _execute_20
    return meth(self, args_10style, kwargs_10style, execution_options)
  File "D:\OTUS\venv\lib\site-packages\sqlalchemy\sql\elements.py", line 323, in _execute_on_connection
    return connection._execute_clauseelement(
  File "D:\OTUS\venv\lib\site-packages\sqlalchemy\engine\base.py", line 1478, in _execute_clauseelement
    ret = self._execute_context(
  File "D:\OTUS\venv\lib\site-packages\sqlalchemy\engine\base.py", line 1842, in _execute_context
    self._handle_dbapi_exception(
  File "D:\OTUS\venv\lib\site-packages\sqlalchemy\engine\base.py", line 2023, in _handle_dbapi_exception
    util.raise_(
  File "D:\OTUS\venv\lib\site-packages\sqlalchemy\util\compat.py", line 207, in raise_
    raise exception
  File "D:\OTUS\venv\lib\site-packages\sqlalchemy\engine\base.py", line 1799, in _execute_context
    self.dialect.do_execute(
  File "D:\OTUS\venv\lib\site-packages\sqlalchemy\engine\default.py", line 717, in do_execute
    cursor.execute(statement, parameters)
sqlalchemy.exc.IntegrityError: (sqlite3.IntegrityError) NOT NULL constraint failed: posts.author_id
[SQL: INSERT INTO posts (title, created_at, author_id) VALUES (?, ?, ?)]
[parameters: ('Flask lesson', '2021-12-12 19:17:30.091338', None)]
(Background on this error at: https://sqlalche.me/e/14/gkpj)

Process finished with exit code 1
